<?xml version="1.0"?>
<sdf version="1.5">
       <model name="MiniTestingRobot">


        <static>false</static>
        <!--  <plugin name="robot_drive" filename="librobot_drive.so"/>-->
        <link name='chassis'>
                 <pose>0 0 .1 0 0 0</pose>
                 <collision name='collision'>
                   <geometry>
                     <box>
                       <size>.4 .2 .1</size>
                     </box>
                   </geometry>
                 </collision>

                 <visual name='visual'>
                   <geometry>
                     <box>
                       <size>.4 .2 .1</size>
                     </box>
                   </geometry>
                 </visual>

                 <collision name='caster_collision'>
                   <pose>-0.15 0 -0.05 0 0 0</pose>
                   <geometry>
                     <sphere>
                     <radius>.05</radius>
                   </sphere>
                 </geometry>

                 <surface>
                   <friction>
                     <ode>
                       <mu>0</mu>
                       <mu2>0</mu2>
                       <slip1>1.0</slip1>
                       <slip2>1.0</slip2>
                     </ode>
                   </friction>
                 </surface>
               </collision>

               <visual name='caster_visual'>
                 <pose>-0.15 0 -0.05 0 0 0</pose>
                 <geometry>
                   <sphere>
                     <radius>.05</radius>
                   </sphere>
                 </geometry>
               </visual>
             </link>


             <link name="leftFront">
               <pose>0.1 0.13 0.1 0 1.5707 1.5707</pose>
               <collision name="collision">
                 <geometry>
                   <cylinder>
                     <radius>.1</radius>
                     <length>.05</length>
                   </cylinder>
                 </geometry>
               </collision>
               <visual name="visual">
                 <geometry>
                   <cylinder>
                     <radius>.1</radius>
                     <length>.05</length>
                   </cylinder>
                 </geometry>
               </visual>
             </link>

             <link name="rightFront">

               <pose>0.1 -0.13 0.1 0 1.5707 1.5707</pose>
               <collision name="collision">
                 <geometry>
                   <cylinder>
                     <radius>.1</radius>
                     <length>.05</length>
                   </cylinder>
                 </geometry>
               </collision>
               <visual name="visual">
                 <geometry>
                   <cylinder>
                     <radius>.1</radius>
                     <length>.05</length>
                   </cylinder>
                 </geometry>
               </visual>
             </link>

             <link name="leftBack">
               <pose>-0.1 0.13 0.1 0 1.5707 1.5707</pose>
               <collision name="collision">
                 <geometry>
                   <cylinder>
                     <radius>.1</radius>
                     <length>.05</length>
                   </cylinder>
                 </geometry>
               </collision>
               <visual name="visual">
                 <geometry>
                   <cylinder>
                     <radius>.1</radius>
                     <length>.05</length>
                   </cylinder>
                 </geometry>
               </visual>
             </link>

             <link name="rightBack">

               <pose>-0.1 -0.13 0.1 0 1.5707 1.5707</pose>
               <collision name="collision">
                 <geometry>
                   <cylinder>
                     <radius>.1</radius>
                     <length>.05</length>
                   </cylinder>
                 </geometry>
               </collision>
               <visual name="visual">
                 <geometry>
                   <cylinder>
                     <radius>.1</radius>
                     <length>.05</length>
                   </cylinder>
                 </geometry>
               </visual>
             </link>



 <joint type="revolute" name="left_front_hinge">
        <pose>0 0 -0.03 0 0 0</pose>
        <child>leftFront</child>
        <parent>chassis</parent>
        <axis>
          <xyz>0 1 0</xyz>
        </axis>
      </joint>

      <joint type="revolute" name="right_front_hinge">
        <pose>0 0 0.03 0 0 0</pose>
        <child>rightFront</child>
        <parent>chassis</parent>
        <axis>
          <xyz>0 1 0</xyz>
        </axis>
      </joint>

      <joint type="revolute" name="left_back_hinge">
             <pose>0 0 -0.03 0 0 0</pose>
             <child>leftBack</child>
             <parent>chassis</parent>
             <axis>
               <xyz>0 1 0</xyz>
             </axis>
           </joint>

           <joint type="revolute" name="right_back_hinge">
             <pose>0 0 0.03 0 0 0</pose>
             <child>rightBack</child>
             <parent>chassis</parent>
             <axis>
               <xyz>0 1 0</xyz>
             </axis>
           </joint>



             <plugin name="gazebo_ros_control" filename="libgazebo_ros_control.so" />
              <plugin name="skid_steer_drive_controller" filename="libgazebo_ros_skid_steer_drive.so">
                <alwaysOn>1</alwaysOn>
                <updateRate>100.0</updateRate>
                <robotNamespace></robotNamespace>
                <leftFrontJoint>left_front_joint</leftFrontJoint>
                <rightFrontJoint>right_front_joint</rightFrontJoint>
                <leftRearJoint>left_back_hinge</leftRearJoint>
                <rightRearJoint>right_back_hinge</rightRearJoint>
                <wheelSeparation>.2</wheelSeparation>
                <wheelDiameter>.1</wheelDiameter>
                <torque>100</torque>
                <broadcastTF>1</broadcastTF>
                <odometryFrame>map</odometryFrame>
                <commandTopic>cmd_vel</commandTopic>
                <odometryTopic>odom</odometryTopic>
                <robotBaseFrame>base_footprint</robotBaseFrame><!--base_footprint-->
                <covariance_x>0.0001</covariance_x>
                <covariance_y>0.0001</covariance_y>
                <covariance_z>0.0001</covariance_z>
                <covariance_yaw>0.0001</covariance_yaw>
              </plugin>


    </model>
</sdf>
